Workbook

Sheet Products
A1: Product ID | B1: Product Name | C1: Category / Segment | D1: Asking Price (TK/pc) | E1: Max Discount (TK/pc) | F1: Lowest Price (TK/pc) | G1: Bundle Size (pcs) | H1: Bundle Price at Asking (TK) | I1: MOQ (bundles) | J1: Fit | K1: Color / Wash | L1: Fabric | M1: Style / Key Features | N1: Sizes | O1: Size Assortment per Bundle | P1: Stock (bundles) | Q1: Stock Status | R1: Dispatch Time | S1: Full Details | T1: Search Keywords | U1: Catalog Batch (20 per batch) | V1: Image File Name | W1: Image URL (Cloudinary) | X1: Active | Y1: Demo-filled Fields (original sheet)
A2: PD011 | B2: Men's Slim Fit Jeans – Light Blue Wash | C2: Adult Male | D2: 700 | E2: =Business_Info!$B$3 -> 20 | F2: =D2-E2 -> 680 | G2: 30 | H2: =D2*G2 -> 21000 | I2: 1 | J2: Slim Fit | K2: Light Blue Wash | L2: Denim (98% Cotton, 2% Spandex) | M2: 5 Pocket | N2: 28–36 | O2: 28×6, 30×6, 32×6, 34×6, 36×6 | P2: 0 | Q2: Made to Order | R2: 15–20 days (production) | S2: Denim (98% Cotton, 2% Spandex), Slim Fit, Light Blue Wash, 5 Pocket | T2: adult male, blue, light, men, pocket, slim, stretch | U2: 1 | V2: PD011_Adult_Male.png | W2: https://res.cloudinary.com/sdquiuat/image/upload/PD011_Adult_Male.png | X2: Yes | Y2: Sizes
A3: PD012 | B3: Men's Regular Fit Jeans – Washed Black | C3: Adult Male | D3: 750 | E3: =Business_Info!$B$3 -> 20 | F3: =D3-E3 -> 730 | G3: 30 | H3: =D3*G3 -> 22500 | I3: 1 | J3: Regular Fit | K3: Washed Black | L3: Denim (100% Cotton) | M3: Ripped Design | N3: 28–38 | O3: 28×5, 30×5, 32×5, 34×5, 36×5, 38×5 | P3: 34 | Q3: In Stock | R3: 2–3 days | S3: Denim (100% Cotton), Regular Fit, Washed Black, Ripped Design | T3: adult male, black, design, men, regular, ripped, washed | U3: 1 | V3: PD012_Adult_Male.png | W3: https://res.cloudinary.com/sdquiuat/image/upload/PD012_Adult_Male.png | X3: Yes | Y3: Sizes
A4: PD013 | B4: Men's Straight Fit Jeans – Dark Blue | C4: Adult Male | D4: 650 | E4: =Business_Info!$B$3 -> 20 | F4: =D4-E4 -> 630 | G4: 30 | H4: =D4*G4 -> 19500 | I4: 1 | J4: Straight Fit | K4: Dark Blue | L4: Denim (100% Cotton) | M4: Clean Look | N4: 28–38 | O4: 28×5, 30×5, 32×5, 34×5, 36×5, 38×5 | P4: 0 | Q4: Made to Order | R4: 15–20 days (production) | S4: Denim (100% Cotton), Straight Fit, Dark Blue, Clean Look | T4: adult male, blue, clean, dark, look, men, straight | U4: 1 | V4: PD013_Adult_Male.png | W4: https://res.cloudinary.com/sdquiuat/image/upload/PD013_Adult_Male.png | X4: Yes | Y4: Sizes
A5: PD014 | B5: Women's Wide Leg Jeans – Light Blue | C5: Adult Female | D5: 700 | E5: =Business_Info!$B$3 -> 20 | F5: =D5-E5 -> 680 | G5: 30 | H5: =D5*G5 -> 21000 | I5: 1 | J5: Wide Leg | K5: Light Blue | L5: Denim (98% Cotton, 2% Spandex) | M5: High Waist | N5: 26–36 | O5: 26×5, 28×5, 30×5, 32×5, 34×5, 36×5 | P5: 0 | Q5: Made to Order | R5: 15–20 days (production) | S5: Denim (98% Cotton, 2% Spandex), Wide Leg, Light Blue, High Waist | T5: adult female, blue, high, leg, light, stretch, waist, wide, women | U5: 1 | V5: PD014_Adult_Female.png | W5: https://res.cloudinary.com/sdquiuat/image/upload/PD014_Adult_Female.png | X5: Yes | Y5: Sizes
A6: PD015 | B6: Women's Flare Fit Jeans – Black | C6: Adult Female | D6: 750 | E6: =Business_Info!$B$3 -> 20 | F6: =D6-E6 -> 730 | G6: 30 | H6: =D6*G6 -> 22500 | I6: 1 | J6: Flare Fit | K6: Black | L6: Denim (98% Cotton, 2% Spandex) | M6: High Waist | N6: 26–34 | O6: 26×6, 28×6, 30×6, 32×6, 34×6 | P6: 9 | Q6: In Stock | R6: 2–3 days | S6: Denim (98% Cotton, 2% Spandex), Flare Fit, Black, High Waist | T6: adult female, black, flare, high, stretch, waist, women | U6: 1 | V6: PD015_Adult_Female.png | W6: https://res.cloudinary.com/sdquiuat/image/upload/PD015_Adult_Female.png | X6: Yes | Y6: Sizes
A7: PD016 | B7: Women's Skinny Fit Jeans – Mid Blue | C7: Adult Female | D7: 650 | E7: =Business_Info!$B$3 -> 20 | F7: =D7-E7 -> 630 | G7: 30 | H7: =D7*G7 -> 19500 | I7: 1 | J7: Skinny Fit | K7: Mid Blue | L7: Denim (98% Cotton, 2% Spandex) | M7: Ripped | N7: 26–34 | O7: 26×6, 28×6, 30×6, 32×6, 34×6 | P7: 7 | Q7: In Stock | R7: 2–3 days | S7: Denim (98% Cotton, 2% Spandex), Skinny Fit, Mid Blue, Ripped | T7: adult female, blue, mid, ripped, skinny, stretch, women | U7: 1 | V7: PD016_Adult_Female.png | W7: https://res.cloudinary.com/sdquiuat/image/upload/PD016_Adult_Female.png | X7: Yes | Y7: Sizes
A8: PD017 | B8: Boys' Regular Fit Jeans – Dark Blue | C8: Kids Boy | D8: 550 | E8: =Business_Info!$B$3 -> 20 | F8: =D8-E8 -> 530 | G8: 30 | H8: =D8*G8 -> 16500 | I8: 1 | J8: Regular Fit | K8: Dark Blue | L8: Denim (100% Cotton) | M8: Cargo Pocket | N8: 5–14 Years | O8: 5Y×6, 7Y×6, 9Y×6, 11Y×6, 13Y×6 | P8: 23 | Q8: In Stock | R8: 2–3 days | S8: Denim (100% Cotton), Regular Fit, Dark Blue, Cargo Pocket | T8: blue, boys kids, cargo, dark, kids boy, pocket, regular | U8: 1 | V8: PD017_Kids_Boy.png | W8: https://res.cloudinary.com/sdquiuat/image/upload/PD017_Kids_Boy.png | X8: Yes | Y8: Sizes
A9: PD018 | B9: Boys' Regular Fit Jeans – Light Blue | C9: Kids Boy | D9: 500 | E9: =Business_Info!$B$3 -> 20 | F9: =D9-E9 -> 480 | G9: 30 | H9: =D9*G9 -> 15000 | I9: 1 | J9: Regular Fit | K9: Light Blue | L9: Denim (98% Cotton, 2% Spandex) | M9: Printed Design | N9: 5–14 Years | O9: 5Y×6, 7Y×6, 9Y×6, 11Y×6, 13Y×6 | P9: 6 | Q9: In Stock | R9: 2–3 days | S9: Denim (98% Cotton, 2% Spandex), Regular Fit, Light Blue, Printed Design | T9: blue, boys kids, design, kids boy, light, printed, regular, stretch | U9: 1 | V9: PD018_Kids_Boy.png | W9: https://res.cloudinary.com/sdquiuat/image/upload/PD018_Kids_Boy.png | X9: Yes | Y9: Sizes
A10: PD019 | B10: Girls' Regular Fit Jeans – Mid Blue | C10: Kids Girl | D10: 500 | E10: =Business_Info!$B$3 -> 20 | F10: =D10-E10 -> 480 | G10: 30 | H10: =D10*G10 -> 15000 | I10: 1 | J10: Regular Fit | K10: Mid Blue | L10: Denim (98% Cotton, 2% Spandex) | M10: Embroidery | N10: 4–12 Years | O10: 4Y×6, 6Y×6, 8Y×6, 10Y×6, 12Y×6 | P10: 0 | Q10: Made to Order | R10: 15–20 days (production) | S10: Denim (98% Cotton, 2% Spandex), Regular Fit, Mid Blue, Embroidery | T10: blue, embroidery, girls kids, kids girl, mid, regular, stretch | U10: 1 | V10: PD019_Kids_Girl.png | W10: https://res.cloudinary.com/sdquiuat/image/upload/PD019_Kids_Girl.png | X10: Yes | Y10: Sizes
A11: PD020 | B11: Girls' Regular Fit Jeans – Pink | C11: Kids Girl | D11: 450 | E11: =Business_Info!$B$3 -> 20 | F11: =D11-E11 -> 430 | G11: 30 | H11: =D11*G11 -> 13500 | I11: 1 | J11: Regular Fit | K11: Pink | L11: Denim (98% Cotton, 2% Spandex) | M11: Embroidery | N11: 4–12 Years | O11: 4Y×6, 6Y×6, 8Y×6, 10Y×6, 12Y×6 | P11: 22 | Q11: In Stock | R11: 2–3 days | S11: Denim (98% Cotton, 2% Spandex), Regular Fit, Pink, Embroidery | T11: embroidery, girls kids, kids girl, pink, regular, stretch | U11: 1 | V11: PD020_Kids_Girl.png | W11: https://res.cloudinary.com/sdquiuat/image/upload/PD020_Kids_Girl.png | X11: Yes | Y11: Sizes
A12: PD021 | B12: Men's Tapered Fit Jeans – Mid Blue Wash | C12: Adult Male | D12: 690 | E12: =Business_Info!$B$3 -> 20 | F12: =D12-E12 -> 670 | G12: 24 | H12: =D12*G12 -> 16560 | I12: 1 | J12: Tapered Fit | K12: Mid Blue Wash | L12: 98% Cotton / 2% Elastane | M12: Classic 5 Pocket, Light Whiskering | N12: 28–36 | O12: 28×5, 30×5, 32×5, 34×5, 36×4 | P12: 0 | Q12: Made to Order | R12: 15–20 days (production) | S12: Tapered Fit, Mid Blue Wash, 98% Cotton, 2% Elastane | T12: adult male, blue, classic, light, men, mid, pocket, stretch, tapered, whiskering | U12: 1 | V12: PD021_Adult_Male.png | W12: https://res.cloudinary.com/sdquiuat/image/upload/PD021_Adult_Male.png | X12: Yes | Y12: Style / Key Features, Sizes
A13: PD022 | B13: Men's Straight Fit Jeans – Vintage Grey Wash | C13: Adult Male | D13: 760 | E13: =Business_Info!$B$3 -> 20 | F13: =D13-E13 -> 740 | G13: 20 | H13: =D13*G13 -> 15200 | I13: 1 | J13: Straight Fit | K13: Vintage Grey Wash | L13: Heavy Denim | M13: Clean Finish | N13: 28–38 | O13: 28×3, 30×3, 32×4, 34×4, 36×3, 38×3 | P13: 12 | Q13: In Stock | R13: 2–3 days | S13: Straight Fit, Vintage Grey Wash, Heavy Denim, Clean Finish | T13: adult male, clean, finish, grey, heavy, men, straight, vintage | U13: 1 | V13: PD022_Adult_Male.png | W13: https://res.cloudinary.com/sdquiuat/image/upload/PD022_Adult_Male.png | X13: Yes | Y13: Sizes
... A92: PD101 | B92: Men's Slim Tapered Fit Jeans – Dark Indigo | C92: Adult Male | D92: 750 | E92: =Business_Info!$B$3 -> 20 | F92: =D92-E92 -> 730 | G92: 30 | H92: =D92*G92 -> 22500 | I92: 1 | J92: Slim Tapered Fit | K92: Dark Indigo | L92: Stretch Denim | M92: Distressed Knee Detail, Premium Stretch Denim | N92: 28–36 | O92: 28×6, 30×6, 32×6, 34×6, 36×6 | P92: 1 | Q92: Low Stock | R92: 2–3 days | S92: Distressed Knee Detail, Dark Indigo Wash, Premium Stretch Denim | T92: adult male, dark, distressed, indigo, knee, men, slim, stretch, tapered | U92: 5 | V92: PD101_Adult_Male.png | W92: https://res.cloudinary.com/sdquiuat/image/upload/PD101_Adult_Male.png | X92: Yes | Y92: Full Details
A93: PD102 | B93: Men's Straight Fit Jeans – Graphite Black | C93: Adult Male | D93: 700 | E93: =Business_Info!$B$3 -> 20 | F93: =D93-E93 -> 680 | G93: 24 | H93: =D93*G93 -> 16800 | I93: 1 | J93: Straight Fit | K93: Graphite Black | L93: Heavy Non-Stretch Denim | M93: Durable Heavy Denim | N93: 28–38 | O93: 28×4, 30×4, 32×4, 34×4, 36×4, 38×4 | P93: 21 | Q93: In Stock | R93: 2–3 days | S93: Clean Straight Fit, Graphite Black Wash, Durable Heavy Denim | T93: adult male, black, durable, graphite, heavy, men, non-stretch, straight, stretch | U93: 5 | V93: PD102_Adult_Male.png | W93: https://res.cloudinary.com/sdquiuat/image/upload/PD102_Adult_Male.png | X93: Yes
A94: PD103 | B94: Men's Relaxed Fit Jeans – Light Blue | C94: Adult Male | D94: 730 | E94: =Business_Info!$B$3 -> 20 | F94: =D94-E94 -> 710 | G94: 30 | H94: =D94*G94 -> 21900 | I94: 1 | J94: Relaxed Fit | K94: Light Blue | L94: Comfort Stretch Denim | M94: Classic 5 Pocket, Light Vintage Fade | N94: 28–38 | O94: 28×5, 30×5, 32×5, 34×5, 36×5, 38×5 | P94: 0 | Q94: Made to Order | R94: 15–20 days (production) | S94: Relaxed Fit, Light Vintage Wash, Comfort Stretch Denim | T94: adult male, blue, classic, comfort, fade, light, men, pocket, relaxed, stretch, vintage | U94: 5 | V94: PD103_Adult_Male.png | W94: https://res.cloudinary.com/sdquiuat/image/upload/PD103_Adult_Male.png | X94: Yes | Y94: Style / Key Features
A95: PD104 | B95: Women's Wide Leg Fit Jeans – Ice Blue | C95: Adult Female | D95: 780 | E95: =Business_Info!$B$3 -> 20 | F95: =D95-E95 -> 760 | G95: 24 | H95: =D95*G95 -> 18720 | I95: 1 | J95: Wide Leg Fit | K95: Ice Blue | L95: Soft Stretch Denim | M95: High-Waist Wide Leg, Premium Soft Stretch Denim | N95: 26–34 | O95: 26×5, 28×5, 30×5, 32×5, 34×4 | P95: 21 | Q95: In Stock | R95: 2–3 days | S95: High-Waist Wide Leg, Ice Blue Wash, Premium Soft Stretch Denim | T95: adult female, blue, high-waist, ice, leg, stretch, wide, women | U95: 5 | V95: PD104_Adult_Female.png | W95: https://res.cloudinary.com/sdquiuat/image/upload/PD104_Adult_Female.png | X95: Yes
A96: PD105 | B96: Women's Flare Fit Jeans – Jet Black | C96: Adult Female | D96: 740 | E96: =Business_Info!$B$3 -> 20 | F96: =D96-E96 -> 720 | G96: 20 | H96: =D96*G96 -> 14800 | I96: 1 | J96: Flare Fit | K96: Jet Black | L96: Fashion Denim | M96: Clean Fashion Finish | N96: 26–34 | O96: 26×4, 28×4, 30×4, 32×4, 34×4 | P96: 16 | Q96: In Stock | R96: 2–3 days | S96: High-Rise Flare Fit, Jet Black Wash, Clean Fashion Finish | T96: adult female, black, clean, fashion, finish, flare, jet, women | U96: 5 | V96: PD105_Adult_Female.png | W96: https://res.cloudinary.com/sdquiuat/image/upload/PD105_Adult_Female.png | X96: Yes
A97: PD106 | B97: Women's Skinny Fit Jeans – Mid Blue | C97: Adult Female | D97: 720 | E97: =Business_Info!$B$3 -> 20 | F97: =D97-E97 -> 700 | G97: 24 | H97: =D97*G97 -> 17280 | I97: 1 | J97: Skinny Fit | K97: Mid Blue | L97: Stretch Denim | M97: Subtle Distressed Detail | N97: 26–34 | O97: 26×5, 28×5, 30×5, 32×5, 34×4 | P97: 26 | Q97: In Stock | R97: 2–3 days | S97: Skinny Fit, Mid Blue Wash, Subtle Distressed Detail, Stretch Denim | T97: adult female, blue, distressed, mid, skinny, stretch, subtle, women | U97: 5 | V97: PD106_Adult_Female.png | W97: https://res.cloudinary.com/sdquiuat/image/upload/PD106_Adult_Female.png | X97: Yes | Y97: Full Details
A98: PD107 | B98: Boys' Cargo Fit Jeans – Dark Blue | C98: Kids Boy | D98: 560 | E98: =Business_Info!$B$3 -> 20 | F98: =D98-E98 -> 540 | G98: 30 | H98: =D98*G98 -> 16800 | I98: 1 | J98: Cargo Fit | K98: Dark Blue | L98: Flexible Kids Denim | M98: Utility Pocket Design | N98: 4–14 Years | O98: 4Y×5, 6Y×5, 8Y×5, 10Y×5, 12Y×5, 14Y×5 | P98: 22 | Q98: In Stock | R98: 2–3 days | S98: Cargo Fit, Dark Blue Wash, Utility Pocket Design, Flexible Kids Denim | T98: blue, boys kids, cargo, dark, design, flexible, kids, kids boy, pocket, utility | U98: 5 | V98: PD107_Kids_Boy.png | W98: https://res.cloudinary.com/sdquiuat/image/upload/PD107_Kids_Boy.png | X98: Yes | Y98: Full Details
A99: PD108 | B99: Boys' Regular Fit Jeans – Light Blue | C99: Kids Boy | D99: 540 | E99: =Business_Info!$B$3 -> 20 | F99: =D99-E99 -> 520 | G99: 28 | H99: =D99*G99 -> 15120 | I99: 1 | J99: Regular Fit | K99: Light Blue | L99: Stretch Kids Denim | M99: Sport Patch Detail | N99: 4–14 Years | O99: 4Y×4, 6Y×5, 8Y×5, 10Y×5, 12Y×5, 14Y×4 | P99: 26 | Q99: In Stock | R99: 2–3 days | S99: Regular Fit, Light Blue Wash, Sport Patch Detail, Stretch Kids Denim | T99: blue, boys kids, kids, kids boy, light, patch, regular, sport, stretch | U99: 5 | V99: PD108_Kids_Boy.png | W99: https://res.cloudinary.com/sdquiuat/image/upload/PD108_Kids_Boy.png | X99: Yes | Y99: Full Details
A100: PD109 | B100: Girls' Wide Leg Fit Jeans – Light Blue | C100: Kids Girl | D100: 550 | E100: =Business_Info!$B$3 -> 20 | F100: =D100-E100 -> 530 | G100: 30 | H100: =D100*G100 -> 16500 | I100: 1 | J100: Wide Leg Fit | K100: Light Blue | L100: Soft Stretch Denim | M100: Floral Embroidery, Soft Kids Denim | N100: 4–14 Years | O100: 4Y×5, 6Y×5, 8Y×5, 10Y×5, 12Y×5, 14Y×5 | P100: 37 | Q100: In Stock | R100: 2–3 days | S100: Wide Leg Fit, Light Blue Wash, Floral Embroidery, Soft Kids Denim | T100: blue, embroidery, floral, girls kids, kids, kids girl, leg, light, stretch, wide | U100: 5 | V100: PD109_Kids_Girl.png | W100: https://res.cloudinary.com/sdquiuat/image/upload/PD109_Kids_Girl.png | X100: Yes | Y100: Full Details
A101: PD110 | B101: Girls' Flared Fit Jeans – Dark Blue | C101: Kids Girl | D101: 580 | E101: =Business_Info!$B$3 -> 20 | F101: =D101-E101 -> 560 | G101: 24 | H101: =D101*G101 -> 13920 | I101: 1 | J101: Flared Fit | K101: Dark Blue | L101: Stretch Kids Denim | M101: Heart Patch Detail | N101: 4–14 Years | O101: 4Y×4, 6Y×4, 8Y×4, 10Y×4, 12Y×4, 14Y×4 | P101: 27 | Q101: In Stock | R101: 2–3 days | S101: Flared Fit, Dark Blue Wash, Heart Patch Detail, Stretch Kids Denim | T101: blue, dark, flared, girls kids, heart, kids, kids girl, patch, stretch | U101: 5 | V101: PD110_Kids_Girl.png | W101: https://res.cloudinary.com/sdquiuat/image/upload/PD110_Kids_Girl.png | X101: Yes | Y101: Full Details
A102: PD111 | B102: Men's Slim Fit Jeans – Light Indigo | C102: Adult Male | D102: 760 | E102: =Business_Info!$B$3 -> 20 | F102: =D102-E102 -> 740 | G102: 24 | H102: =D102*G102 -> 18240 | I102: 1 | J102: Slim Fit | K102: Light Indigo | L102: Premium Stretch Denim | M102: Heavy Distressed Knee Design, Tapered Leg | N102: 28–36 | O102: 28×5, 30×5, 32×5, 34×5, 36×4 | P102: 0 | Q102: Made to Order | R102: 15–20 days (production) | S102: Heavy Distressed Knee Design, Light Indigo Wash, Tapered Leg | T102: adult male, design, distressed, heavy, indigo, knee, leg, light, men, slim, stretch, tapered | U102: 6 | V102: PD111_Adult_Male.png | W102: https://res.cloudinary.com/sdquiuat/image/upload/PD111_Adult_Male.png | X102: Yes
A103: PD112 | B103: Men's Straight Fit Jeans – Washed Black | C103: Adult Male | D103: 700 | E103: =Business_Info!$B$3 -> 20 | F103: =D103-E103 -> 680 | G103: 20 | H103: =D103*G103 -> 14000 | I103: 1 | J103: Straight Fit | K103: Washed Black | L103: Heavy Non-Stretch Denim | M103: Clean Straight Cut, Reinforced Classic Pockets | N103: 28–38 | O103: 28×3, 30×3, 32×4, 34×4, 36×3, 38×3 | P103: 23 | Q103: In Stock | R103: 2–3 days | S103: Clean Straight Cut, Washed Black Finish, Reinforced Classic Pockets | T103: adult male, black, classic, clean, cut, heavy, men, non-stretch, pockets, reinforced, straight, stretch, washed | U103: 6 | V103: PD112_Adult_Male.png | W103: https://res.cloudinary.com/sdquiuat/image/upload/PD112_Adult_Male.png | X103: Yes
A104: PD113 | B104: Men's Cargo Fit Jeans – Mid Blue | C104: Adult Male | D104: 780 | E104: =Business_Info!$B$3 -> 20 | F104: =D104-E104 -> 760 | G104: 18 | H104: =D104*G104 -> 14040 | I104: 1 | J104: Cargo Fit | K104: Mid Blue | L104: Comfort Stretch Denim | M104: Utility Cargo Pockets, Relaxed Workwear Styling | N104: 28–38 | O104: 28×3, 30×3, 32×3, 34×3, 36×3, 38×3 | P104: 29 | Q104: In Stock | R104: 2–3 days | S104: Utility Cargo Pockets, Mid Blue Wash, Relaxed Workwear Styling | T104: adult male, blue, cargo, comfort, men, mid, pockets, relaxed, stretch, styling, utility, workwear | U104: 6 | V104: PD113_Adult_Male.png | W104: https://res.cloudinary.com/sdquiuat/image/upload/PD113_Adult_Male.png | X104: Yes
A105: PD114 | B105: Women's Wide Leg Fit Jeans – Light Blue | C105: Adult Female | D105: 770 | E105: =Business_Info!$B$3 -> 20 | F105: =D105-E105 -> 750 | G105: 24 | H105: =D105*G105 -> 18480 | I105: 1 | J105: Wide Leg Fit | K105: Light Blue | L105: Soft Stretch Denim | M105: High Waist Wide Leg, Distressed Knee Detail | N105: 26–34 | O105: 26×5, 28×5, 30×5, 32×5, 34×4 | P105: 28 | Q105: In Stock | R105: 2–3 days | S105: High Waist Wide Leg, Distressed Knee Detail, Soft Light Wash | T105: adult female, blue, distressed, high, knee, leg, light, stretch, waist, wide, women | U105: 6 | V105: PD114_Adult_Female.png | W105: https://res.cloudinary.com/sdquiuat/image/upload/PD114_Adult_Female.png | X105: Yes
A106: PD115 | B106: Women's Flared Fit Jeans – Jet Black | C106: Adult Female | D106: 740 | E106: =Business_Info!$B$3 -> 20 | F106: =D106-E106 -> 720 | G106: 20 | H106: =D106*G106 -> 14800 | I106: 1 | J106: Flared Fit | K106: Jet Black | L106: Premium Fashion Denim | M106: High Rise Flared Cut, Clean Minimal Finish | N106: 26–34 | O106: 26×4, 28×4, 30×4, 32×4, 34×4 | P106: 9 | Q106: In Stock | R106: 2–3 days | S106: High Rise Flared Cut, Jet Black Wash, Clean Minimal Finish | T106: adult female, black, clean, cut, fashion, finish, flared, high, jet, minimal, rise, women | U106: 6 | V106: PD115_Adult_Female.png | W106: https://res.cloudinary.com/sdquiuat/image/upload/PD115_Adult_Female.png | X106: Yes
A107: PD116 | B107: Women's Flared Fit Jeans – Mid Blue | C107: Adult Female | D107: 730 | E107: =Business_Info!$B$3 -> 20 | F107: =D107-E107 -> 710 | G107: 22 | H107: =D107*G107 -> 16060 | I107: 1 | J107: Flared Fit | K107: Mid Blue | L107: Stretch Denim | M107: Light Distressed Detail, Flexible Comfort Denim | N107: 26–34 | O107: 26×4, 28×5, 30×5, 32×4, 34×4 | P107: 13 | Q107: In Stock | R107: 2–3 days | S107: Mid Blue Flare, Light Distressed Detail, Flexible Comfort Denim | T107: adult female, blue, comfort, distressed, flared, flexible, light, mid, stretch, women | U107: 6 | V107: PD116_Adult_Female.png | W107: https://res.cloudinary.com/sdquiuat/image/upload/PD116_Adult_Female.png | X107: Yes
A108: PD117 | B108: Boys' Regular Fit Jeans – Dark Blue | C108: Kids Boy | D108: 560 | E108: =Business_Info!$B$3 -> 20 | F108: =D108-E108 -> 540 | G108: 30 | H108: =D108*G108 -> 16800 | I108: 1 | J108: Regular Fit | K108: Dark Blue | L108: Stretch Kids Denim | M108: Sport Patch Design, Durable Everyday Kids Denim | N108: 4–14 Years | O108: 4Y×5, 6Y×5, 8Y×5, 10Y×5, 12Y×5, 14Y×5 | P108: 0 | Q108: Made to Order | R108: 15–20 days (production) | S108: Sport Patch Design, Dark Blue Wash, Durable Everyday Kids Denim | T108: blue, boys kids, dark, design, durable, everyday, kids, kids boy, patch, regular, sport, stretch | U108: 6 | V108: PD117_Kids_Boy.png | W108: https://res.cloudinary.com/sdquiuat/image/upload/PD117_Kids_Boy.png | X108: Yes
A109: PD118 | B109: Boys' Jogger Fit Jeans – Light Blue | C109: Kids Boy | D109: 580 | E109: =Business_Info!$B$3 -> 20 | F109: =D109-E109 -> 560 | G109: 28 | H109: =D109*G109 -> 16240 | I109: 1 | J109: Jogger Fit | K109: Light Blue | L109: Stretch Kids Denim | M109: Cargo Jogger Styling, Elastic Hem, Utility Pockets | N109: 4–14 Years | O109: 4Y×4, 6Y×5, 8Y×5, 10Y×5, 12Y×5, 14Y×4 | P109: 5 | Q109: In Stock | R109: 2–3 days | S109: Cargo Jogger Styling, Light Blue Wash, Elastic Hem, Utility Pockets | T109: blue, boys kids, cargo, elastic, hem, jogger, kids, kids boy, light, pockets, stretch, styling, utility | U109: 6 | V109: PD118_Kids_Boy.png | W109: https://res.cloudinary.com/sdquiuat/image/upload/PD118_Kids_Boy.png | X109: Yes
A110: PD119 | B110: Girls' Wide Leg Fit Jeans – Light Blue | C110: Kids Girl | D110: 590 | E110: =Business_Info!$B$3 -> 20 | F110: =D110-E110 -> 570 | G110: 30 | H110: =D110*G110 -> 17700 | I110: 1 | J110: Wide Leg Fit | K110: Light Blue | L110: Stretch Kids Denim | M110: Butterfly & Flower Embroidery, Soft Wide Leg Cut | N110: 4–14 Years | O110: 4Y×5, 6Y×5, 8Y×5, 10Y×5, 12Y×5, 14Y×5 | P110: 5 | Q110: In Stock | R110: 2–3 days | S110: Butterfly & Flower Embroidery, Light Blue Wash, Soft Wide Leg Cut | T110: blue, butterfly, cut, embroidery, flower, girls kids, kids, kids girl, leg, light, stretch, wide | U110: 6 | V110: PD119_Kids_Girl.png | W110: https://res.cloudinary.com/sdquiuat/image/upload/PD119_Kids_Girl.png | X110: Yes
A111: PD120 | B111: Girls' Flared Fit Jeans – Dark Blue | C111: Kids Girl | D111: 600 | E111: =Business_Info!$B$3 -> 20 | F111: =D111-E111 -> 580 | G111: 24 | H111: =D111*G111 -> 14400 | I111: 1 | J111: Flared Fit | K111: Dark Blue | L111: Stretch Kids Denim | M111: Heart Patch Design, Flared Leg with Fun Detail | N111: 4–14 Years | O111: 4Y×4, 6Y×4, 8Y×4, 10Y×4, 12Y×4, 14Y×4 | P111: 30 | Q111: In Stock | R111: 2–3 days | S111: Heart Patch Design, Dark Blue Wash, Flared Leg with Fun Detail | T111: blue, dark, design, flared, fun, girls kids, heart, kids, kids girl, leg, patch, stretch | U111: 6 | V111: PD120_Kids_Girl.png | W111: https://res.cloudinary.com/sdquiuat/image/upload/PD120_Kids_Girl.png | X111: Yes
A112: AM-DJ-001 | B112: Men's Slim Fit Jeans – Dark Indigo | C112: Adult Male | D112: 680 | E112: =Business_Info!$B$3 -> 20 | F112: =D112-E112 -> 660 | G112: 24 | H112: =D112*G112 -> 16320 | I112: 1 | J112: Slim Fit | K112: Dark Indigo | L112: 98% Cotton / 2% Elastane | M112: Whisker Wash | N112: 28–36 | O112: 28×5, 30×5, 32×5, 34×5, 36×4 | P112: 0 | Q112: Made to Order | R112: 15–20 days (production) | S112: Slim Fit, Dark Indigo, Whisker Wash, 98% Cotton 2% Elastane | T112: adult male, dark, indigo, men, slim, stretch, whisker | U112: 6 | V112: AM-DJ-001_Adult_Male.png | W112: https://res.cloudinary.com/sdquiuat/image/upload/AM-DJ-001_Adult_Male.png | X112: Yes | Y112: Sizes
A113: AM-DJ-002 | B113: Men's Straight Fit Jeans – Black Wash | C113: Adult Male | D113: 740 | E113: =Business_Info!$B$3 -> 20 | F113: =D113-E113 -> 720 | G113: 20 | H113: =D113*G113 -> 14800 | I113: 1 | J113: Straight Fit | K113: Black Wash | L113: Durable Denim, Heavyweight Fabric | M113: Classic 5 Pocket, Clean Hem, Faded Black Look | N113: 28–38 | O113: 28×3, 30×3, 32×4, 34×4, 36×3, 38×3 | P113: 7 | Q113: In Stock | R113: 2–3 days | S113: Straight Fit, Black Wash, Durable Denim, Heavyweight Fabric | T113: adult male, black, classic, clean, durable, fabric, faded, heavyweight, hem, look, men, pocket, straight | U113: 6 | V113: AM-DJ-002_Adult_Male.png | W113: https://res.cloudinary.com/sdquiuat/image/upload/AM-DJ-002_Adult_Male.png | X113: Yes | Y113: Style / Key Features, Sizes
A114: AM-DJ-003 | B114: Men's Relaxed Fit Jeans – Stone Wash | C114: Adult Male | D114: 790 | E114: =Business_Info!$B$3 -> 20 | F114: =D114-E114 -> 770 | G114: 18 | H114: =D114*G114 -> 14220 | I114: 1 | J114: Relaxed Fit | K114: Stone Wash, Vintage Blue | L114: Heavyweight Rigid Denim (100% Cotton) | M114: Reinforced Stitching | N114: 28–38 | O114: 28×3, 30×3, 32×3, 34×3, 36×3, 38×3 | P114: 20 | Q114: In Stock | R114: 2–3 days | S114: Relaxed Fit, Stone Wash, Vintage Blue, Reinforced Stitching | T114: adult male, blue, heavyweight, men, reinforced, relaxed, rigid, stitching, stone, vintage | U114: 6 | V114: AM-DJ-003_Adult_Male.png | W114: https://res.cloudinary.com/sdquiuat/image/upload/AM-DJ-003_Adult_Male.png | X114: Yes | Y114: Fabric, Sizes
A115: AF-DJ-001 | B115: Women's High Waist Skinny Jeans – Light Blue Wash | C115: Adult Female | D115: 620 | E115: =Business_Info!$B$3 -> 20 | F115: =D115-E115 -> 600 | G115: 24 | H115: =D115*G115 -> 14880 | I115: 1 | J115: High Waist Skinny | K115: Light Blue Wash | L115: Stretch Denim | M115: Ankle Length | N115: 26–34 | O115: 26×5, 28×5, 30×5, 32×5, 34×4 | P115: 0 | Q115: Made to Order | R115: 15–20 days (production) | S115: High Waist Skinny, Light Blue Wash, Stretch Denim, Ankle Length | T115: adult female, ankle, blue, high, length, light, skinny, stretch, waist, women | U115: 6 | V115: AF-DJ-001_Adult_Female.png | W115: https://res.cloudinary.com/sdquiuat/image/upload/AF-DJ-001_Adult_Female.png | X115: Yes | Y115: Sizes
A116: AF-DJ-002 | B116: Women's Mom Fit Jeans – Medium Blue | C116: Adult Female | D116: 710 | E116: =Business_Info!$B$3 -> 20 | F116: =D116-E116 -> 690 | G116: 22 | H116: =D116*G116 -> 15620 | I116: 1 | J116: Mom Fit | K116: Medium Blue | L116: Soft Washed Denim | M116: Rolled Hem | N116: 26–36 | O116: 26×3, 28×4, 30×4, 32×4, 34×4, 36×3 | P116: 13 | Q116: In Stock | R116: 2–3 days | S116: Mom Fit, Medium Blue, Rolled Hem, Soft Washed Denim | T116: adult female, blue, hem, medium, mom, rolled, washed, women | U116: 6 | V116: AF-DJ-002_Adult_Female.png | W116: https://res.cloudinary.com/sdquiuat/image/upload/AF-DJ-002_Adult_Female.png | X116: Yes | Y116: Sizes
A117: AF-DJ-003 | B117: Women's Wide Leg Jeans – Dark Indigo | C117: Adult Female | D117: 780 | E117: =Business_Info!$B$3 -> 20 | F117: =D117-E117 -> 760 | G117: 16 | H117: =D117*G117 -> 12480 | I117: 1 | J117: Wide Leg | K117: Dark Indigo | L117: Fashion Denim | M117: Premium Finish | N117: 26–36 | O117: 26×2, 28×3, 30×3, 32×3, 34×3, 36×2 | P117: 17 | Q117: In Stock | R117: 2–3 days | S117: Wide Leg, Dark Indigo, Premium Finish, Fashion Denim | T117: adult female, dark, fashion, finish, indigo, leg, wide, women | U117: 6 | V117: AF-DJ-003_Adult_Female.png | W117: https://res.cloudinary.com/sdquiuat/image/upload/AF-DJ-003_Adult_Female.png | X117: Yes | Y117: Sizes
A118: KB-DJ-001 | B118: Boys' Jogger Fit Jeans – Blue Wash | C118: Kids Boy | D118: 450 | E118: =Business_Info!$B$3 -> 20 | F118: =D118-E118 -> 430 | G118: 30 | H118: =D118*G118 -> 13500 | I118: 1 | J118: Jogger Fit | K118: Blue Wash | L118: Soft Kids Denim | M118: Elastic Waist | N118: 4–12 Years | O118: 4Y×6, 6Y×6, 8Y×6, 10Y×6, 12Y×6 | P118: 20 | Q118: In Stock | R118: 2–3 days | S118: Jogger Fit, Elastic Waist, Blue Wash, Soft Kids Denim | T118: blue, boys kids, elastic, jogger, kids, kids boy, waist | U118: 6 | V118: KB-DJ-001_Kids_Boy.png | W118: https://res.cloudinary.com/sdquiuat/image/upload/KB-DJ-001_Kids_Boy.png | X118: Yes | Y118: Sizes
...

Sheet Business_Info
A1: Business Info, Policies & Agent Settings (demo data — edit freely)
A2: Setting / Topic | B2: Value | C2: Notes for the AI Agent
A3: Max Bargain Discount (TK per piece) | B3: 20 | C3: Lowest Price = Asking Price − this value. The agent must never quote below the Lowest Price.
A4: Company Name | B4: Demo Denim Wholesale Ltd. | C4: Fictional demo name — replace with the client's brand.
A5: Business Type | B5: Denim jeans manufacturer & wholesaler (B2B only)
A6: Location | B6: Keraniganj, Dhaka, Bangladesh | C6: Factory visits by appointment via the sales team.
A7: Product Range | B7: Denim jeans — Adult Male, Adult Female, Kids Boy, Kids Girl (120 designs) | C7: No other garment types.
A8: Retail Policy | B8: Wholesale only — no retail / single-piece sales | C8: Politely decline retail requests; set lead status to Retail-Declined.
A9: MOQ | B9: 1 bundle per design (bundle size 16–32 pcs, see Products) | C9: Designs can be mixed; each design ordered in full bundles.
A10: Minimum Order Value | B10: TK 30,000 per order | C10: Demo figure.
A11: Size Assortment | B11: Each bundle comes in the standard size assortment shown in Products | C11: Custom size ratio possible for 5+ bundles of one design (sales team confirms).
A12: Bargaining Rules | B12: Step 1: offer Asking − 10 TK. Step 2 (customer pushes again): final = Lowest Price (Asking − 20 TK). Accept any counter ≥ Lowest Price. | C12: Say "this is our final price" at the Lowest Price. Larger discounts only via sales team for 10+ bundles.
A13: Currency | B13: Bangladeshi Taka (BDT / TK) only | C13: All prices, quotes and invoices are in TK.
A14: Payment Methods | B14: Bank transfer, bKash/Nagad merchant, cash at factory; 50% advance, balance before dispatch
A15: Credit / COD | B15: No credit or cash-on-delivery for new buyers
A16: Samples | B16: Paid samples (1 pc per design); cost adjusted against the bulk order.
A17: Private Label / Customization | B17: Woven label, hangtag, custom wash for 10+ bundles per design; lead time 20–30 days | C17: Forward to the sales team.
A18: Dispatch Time | B18: In stock: 2–3 days. Made to order: 15–20 days | C18: Per-product value in Products.Dispatch Time.
A19: Delivery | B19: All over Bangladesh by courier / transport agency; 1–3 days; buyer pays freight
A20: Defects & Returns | B20: Report defects within 7 days of receipt with photos — replaced or credited. No change-of-mind returns.
A21: Sales Team Hours | B21: Saturday–Thursday, 10:00–19:00 (Bangladesh Time, GMT+6) | C21: The AI agent answers 24/7.
A22: Agent Language | B22: English | C22: Reply in simple, friendly business English even if the customer writes in Bangla (portfolio showcase requirement).
A23: Catalog Sending Rule | B23: Send 20 images per batch, wait 10–20 seconds between batches (6 batches = 120 images) | C23: Protects the WhatsApp number from being flagged. Stop when the customer asks.
A24: Handover Rule | B24: When the customer confirms items, quantities and price, collect lead details, set status "Qualified – Ready for Sales" and notify the sales team
A26: Yellow cells (blue text) are inputs: changing them updates the prices in the Products sheet.

Sheet Customer_FAQ
A1: Likely Customer Questions & How the AI Agent Should Answer
A2: 66 questions in 14 categories · Agent replies in English · Data Source tells the agent where to look the answer up.
A4: # | B4: Category | C4: Sample Customer Question | D4: Intent | E4: How the Agent Should Answer | F4: Data Source
A5: 1 | B5: Greeting | C5: Hi / Hello / Assalamu alaikum | D5: greeting | E5: Greet warmly, introduce the company as a denim jeans manufacturer & wholesaler, ask if they are buying for a business and what segment they need (Men, Women, Boys, Girls). | F5: Business_Info
A6: 2 | B6: Greeting | C6: Who are you? Is this a bot? | D6: identity | E6: Say you are the company's virtual sales assistant; a human sales rep takes over once the order details are ready. | F6: Business_Info
A7: 3 | B7: Business | C7: What do you sell? | D7: about_products | E7: Denim jeans only, 4 segments: Adult Male, Adult Female, Kids Boy, Kids Girl. 120 designs. Offer to send the catalog. | F7: Products / Business_Info
A8: 4 | B8: Business | C8: Are you a manufacturer or a trader? | D8: about_company | E8: Manufacturer + wholesaler with own production in Keraniganj, Dhaka, Bangladesh. | F8: Business_Info
A9: 5 | B9: Business | C9: Where is your factory / shop located? | D9: location | E9: Give the address from Business_Info. Visits by appointment through the sales team. | F9: Business_Info
A10: 6 | B10: Business | C10: What are your business hours? | D10: hours | E10: Assistant replies 24/7; human sales team hours from Business_Info. | F10: Business_Info
A11: 7 | B11: Retail / Wholesale | C11: Can I buy just 1 or 2 pieces? | D11: retail_request | E11: Politely explain we sell wholesale only (minimum 1 bundle per design). Do not continue a retail order. Lead status = Retail-Declined. | F11: Business_Info (MOQ)
A12: 8 | B12: Retail / Wholesale | C12: I want one jeans for myself, price? | D12: retail_request | E12: Same polite wholesale-only reply; thank them and close. Do not quote a single-piece retail price. | F12: Business_Info
A13: 9 | B13: Retail / Wholesale | C13: Do you sell retail or only wholesale? | D13: wholesale_only | E13: Wholesale only. Explain MOQ and bundle concept. | F13: Business_Info
A14: 10 | B14: Retail / Wholesale | C14: What is your minimum order quantity (MOQ)? | D14: moq | E14: MOQ is 1 bundle per design; bundle size differs per design (16–32 pcs). Minimum total order value from Business_Info. | F14: Products.Bundle Size / Business_Info
A15: 11 | B15: Retail / Wholesale | C15: Can I mix designs in one order? | D15: mix_designs | E15: Yes, different designs can be mixed; each design is ordered in full bundles. | F15: Business_Info
A16: 12 | B16: Retail / Wholesale | C16: Can I mix sizes inside a bundle? | D16: size_mix | E16: Bundles come in a standard size assortment (see Size Assortment). Custom ratios possible for 5+ bundles of a design, confirmed by the sales team. | F16: Products.Size Assortment / Business_Info
... A70: 66 | B70: Misc | C70: [Writes in Bangla / other language] | D70: language | E70: Reply in English (project rule) in simple words; optionally acknowledge the language. | F70: —

Sheet Leads_Template
A1: Lead ID | B1: WhatsApp Number | C1: Customer Name | D1: Business Name | E1: Business Type | F1: Country | G1: City | H1: Interested Product IDs | I1: Order Items (ID × bundles @ agreed price) | J1: Total Bundles | K1: Estimated Order Value (TK) | L1: Payment Preference | M1: Delivery Address | N1: Required By | O1: Lead Status | P1: Lead Score (1–5) | Q1: Retail Request? | R1: Conversation Summary | S1: Assigned Sales Rep | T1: First Contact | U1: Last Contact | V1: Handover Notified
A2: L-0001 | B2: +8801XXXXXXXXX | C2: Example Buyer | D2: Example Fashion House | E2: Retailer (shop) | F2: Bangladesh | G2: Chattogram | H2: PD021, PD045 | I2: PD021 × 2 @ TK 680; PD045 × 1 @ TK 720 | J2: 3 | K2: =680*24*2+720*22 -> 48480 | L2: Bank transfer | M2: Example address, Chattogram | N2: 2026-11-01 | O2: Qualified – Ready for Sales | P2: 4 | Q2: No | R2: Liked PD021 & PD045 from batch 2; negotiated PD021 from 690 to 680 (final 670 not needed). | S2: — | T2: 2026-10-13 21:00 | U2: 2026-10-13 21:25 | V2: Yes
A4: Row 2 is an EXAMPLE showing the expected format — the AI agent writes one row per customer (in Airtable). Delete the example before going live.
A5: Lead Status options: New · Browsing Catalog · Negotiating · Collecting Details · Qualified – Ready for Sales · Handed Over · Retail-Declined · Not Interested
A6: Lead Score guide: 5 = items+qty+price agreed & details complete · 4 = items+price agreed · 3 = negotiating · 2 = browsing · 1 = retail / no intent

Sheet Summary
A1: Summary by Category
A3: Category / Segment | B3: Products | C3: Lowest Asking (TK) | D3: Highest Asking (TK) | E3: Average Asking (TK) | F3: In-Stock Designs | G3: Made-to-Order Designs
A4: Adult Male | B4: =COUNTIF(Products!$C$2:$C$121,A4) -> 36 | C4: =_xlfn.MINIFS(Products!$D$2:$D$121,Products!$C$2:$C$121,A4) -> 650 | D4: =_xlfn.MAXIFS(Products!$D$2:$D$121,Products!$C$2:$C$121,A4) -> 800 | E4: =AVERAGEIF(Products!$C$2:$C$121,A4,Products!$D$2:$D$121) -> 746.38889 | F4: =COUNTIFS(Products!$C$2:$C$121,A4,Products!$Q$2:$Q$121,"<>Made to Order") -> 28 | G4: =COUNTIFS(Products!$C$2:$C$121,A4,Products!$Q$2:$Q$121,"Made to Order") -> 8
A5: Adult Female | B5: =COUNTIF(Products!$C$2:$C$121,A5) -> 36 | C5: =_xlfn.MINIFS(Products!$D$2:$D$121,Products!$C$2:$C$121,A5) -> 620 | D5: =_xlfn.MAXIFS(Products!$D$2:$D$121,Products!$C$2:$C$121,A5) -> 790 | E5: =AVERAGEIF(Products!$C$2:$C$121,A5,Products!$D$2:$D$121) -> 721.38889 | F5: =COUNTIFS(Products!$C$2:$C$121,A5,Products!$Q$2:$Q$121,"<>Made to Order") -> 33 | G5: =COUNTIFS(Products!$C$2:$C$121,A5,Products!$Q$2:$Q$121,"Made to Order") -> 3
A6: Kids Boy | B6: =COUNTIF(Products!$C$2:$C$121,A6) -> 24 | C6: =_xlfn.MINIFS(Products!$D$2:$D$121,Products!$C$2:$C$121,A6) -> 450 | D6: =_xlfn.MAXIFS(Products!$D$2:$D$121,Products!$C$2:$C$121,A6) -> 580 | E6: =AVERAGEIF(Products!$C$2:$C$121,A6,Products!$D$2:$D$121) -> 528.75 | F6: =COUNTIFS(Products!$C$2:$C$121,A6,Products!$Q$2:$Q$121,"<>Made to Order") -> 22 | G6: =COUNTIFS(Products!$C$2:$C$121,A6,Products!$Q$2:$Q$121,"Made to Order") -> 2
A7: Kids Girl | B7: =COUNTIF(Products!$C$2:$C$121,A7) -> 24 | C7: =_xlfn.MINIFS(Products!$D$2:$D$121,Products!$C$2:$C$121,A7) -> 420 | D7: =_xlfn.MAXIFS(Products!$D$2:$D$121,Products!$C$2:$C$121,A7) -> 600 | E7: =AVERAGEIF(Products!$C$2:$C$121,A7,Products!$D$2:$D$121) -> 518.75 | F7: =COUNTIFS(Products!$C$2:$C$121,A7,Products!$Q$2:$Q$121,"<>Made to Order") -> 20 | G7: =COUNTIFS(Products!$C$2:$C$121,A7,Products!$Q$2:$Q$121,"Made to Order") -> 4
A8: Total / All | B8: =SUM(B4:B7) -> 120 | C8: =MIN(Products!$D$2:$D$121) -> 420 | D8: =MAX(Products!$D$2:$D$121) -> 800 | E8: =AVERAGE(Products!$D$2:$D$121) -> 649.83333 | F8: =SUM(F4:F7) -> 103 | G8: =SUM(G4:G7) -> 17
